<mujoco model="inverted pendulum">

	<compiler inertiafromgeom="true"/>
	<default>
		<joint armature="0" damping="1"/>
		<geom contype="0" friction="1 0.1 0.1" rgba="0.7 0.7 0 1"/>
		<tendon/>
	</default>

	<option gravity="0 0 0" integrator="RK4" timestep="0.002"/>

	<size nstack="3000"/>

	<worldbody>
		<geom name="cart" pos="0 0 0" quat="0.707 0 0.707 0" size="0.1 0.1" type="capsule"/>
		<body name="pole" pos="0 0 0">
			<joint axis="0 1 0" name="hinge" pos="0 0 0" type="hinge"/>
			<geom fromto="0 0 0 0.001 0 0.6" name="cpole" rgba="0 0.7 0.7 1" size="0.049 0.3" type="capsule"/>
			<!--                 <body name="pole2" pos="0.001 0 0.6"><joint name="hinge2" type="hinge" pos="0 0 0" axis="0 1 0"/><geom name="cpole2" type="capsule" fromto="0 0 0 0 0 0.6" size="0.05 0.3" rgba="0.7 0 0.7 1"/><site name="tip2" pos="0 0 .6"/></body>-->
		</body>
	</worldbody>

	<actuator>
		<general ctrllimited="true" ctrlrange="-1 1" gear="1" joint="hinge" name="hinge" dynprm="0.0333" dyntype="filter"/>
	</actuator>

</mujoco>